Workbook

Sheet README
A1: Task 3a – Excel Display Template (Plug & Play)
A3: How to use (5 mins):
A4: 1) Export your Google Form responses as CSV (Google Forms → Responses → three-dots → Download responses (.csv)).
A5: 2) Open this workbook and go to the 'Raw_Responses' sheet.
A6: 3) Paste the CSV starting in cell A1 (include the header row).
A7: 4) On 'Question_Map', list the exact header text for each question and set the Type to Scale / MCQ / Text, Audience to NonTech/Tech, and (for scales) set ScaleMin and ScaleMax.
A8: 5) Averages, distributions and summaries will populate automatically in the 'Scales_Averages' and 'Scale_Distribution' sheets.
A9: 6) Use the 'MCQ_Summary' sheet by listing an MCQ header and its known options. Counts will fill automatically.
A10: 7) The 'Dashboard' chart will reflect the first 10 scale questions. Extend the chart range if you have more.
A12: Notes:
A13: - This template works best on Excel 365. If you see #NAME? errors, update Excel.
A14: - Keep your header texts in Question_Map EXACTLY matching the first row in Raw_Responses.
A15: - No personal data should be included. Anonymise before sharing.

Sheet Raw_Responses
A1: Timestamp | B1: Audience | C1: I could complete the key tasks without help. | D1: Labels and buttons were clear. | E1: The layout was easy to navigate. | F1: Pages loaded fast enough. | G1: I would trust how my data is handled. | H1: It worked comfortably on my phone/tablet. | I1: Text size/contrast were easy to read. | J1: Overall, it meets my needs. | K1: Which feature was most useful? | L1: What confused you or slowed you down?

Sheet Question_Map
A1: Header | B1: Audience (NonTech/Tech) | C1: Type (Scale/MCQ/Text) | D1: ScaleMin | E1: ScaleMax | F1: Topic/Theme
A2: I could complete the key tasks without help. | B2: NonTech | C2: Scale | D2: 1 | E2: 10 | F2: Usability
A3: Labels and buttons were clear. | B3: NonTech | C3: Scale | D3: 1 | E3: 10 | F3: Navigation
A4: The layout was easy to navigate. | B4: NonTech | C4: Scale | D4: 1 | E4: 10 | F4: Navigation
A5: Pages loaded fast enough. | B5: NonTech | C5: Scale | D5: 1 | E5: 10 | F5: Performance
A6: It worked comfortably on my phone/tablet. | B6: NonTech | C6: Scale | D6: 1 | E6: 10 | F6: Accessibility
A7: Overall, it meets my needs. | B7: NonTech | C7: Scale | D7: 1 | E7: 10 | F7: Satisfaction
A8: Which feature was most useful? | B8: NonTech | C8: MCQ | F8: Usefulness
A9: What confused you or slowed you down and why? | B9: NonTech | C9: Text | F9: Barriers
A10: Top 2 improvements you'd like next | B10: NonTech | C10: Text | F10: Improvements
A11: Anything you liked that I should keep | B11: NonTech | C11: Text | F11: Keep features

Sheet Scales_Averages
A1: Header | B1: Audience | C1: Topic | D1: N | E1: Average | F1: Median | G1: % Top Box (>=Threshold) | H1: Top Box Threshold
A2: =IF(INDEX(Question_Map!$C$2:$C$100,1)="Scale",INDEX(Question_Map!$A$2:$A$100,1),"") -> I could complete the key tasks without help. | B2: =IF($A2<>"",INDEX(Question_Map!$B$2:$B$100,1),"") -> NonTech | C2: =IF($A2<>"",INDEX(Question_Map!$F$2:$F$100,1),"") -> Usability | D2: =IF($A2="","",COUNT(IFERROR(--INDEX(Raw_Responses!$1:$1048576,0,MATCH($A2,Raw_Responses!$1:$1,0)),""))) -> 1 | E2: =IF($A2="","",AVERAGE(IFERROR(--INDEX(Raw_Responses!$1:$1048576,0,MATCH($A2,Raw_Responses!$1:$1,0)),""))) -> 0 | F2: =IF($A2="","",MEDIAN(IFERROR(--INDEX(Raw_Responses!$1:$1048576,0,MATCH($A2,Raw_Responses!$1:$1,0)),""))) -> 0 | G2: =IF($A2="","",IF($H2="","",SUMPRODUCT(--(INDEX(Raw_Responses!$1:$1048576,0,MATCH($A2,Raw_Responses!$1:$1,0))>=$H2))/COUNT(IFERROR(--INDEX(Raw_Responses!$1:$1048576,0,MATCH($A2,Raw_Responses!$1:$1,0)),"")))) -> 1 | H2: =IF($A2="","",IF(INDEX(Question_Map!$E$2:$E$100,1)=10,8,IF(INDEX(Question_Map!$E$2:$E$100,1)=5,4,INDEX(Question_Map!$E$2:$E$100,1)))) -> 8
A3: =IF(INDEX(Question_Map!$C$2:$C$100,2)="Scale",INDEX(Question_Map!$A$2:$A$100,2),"") -> Labels and buttons were clear. | B3: =IF($A3<>"",INDEX(Question_Map!$B$2:$B$100,2),"") -> NonTech | C3: =IF($A3<>"",INDEX(Question_Map!$F$2:$F$100,2),"") -> Navigation | D3: =IF($A3="","",COUNT(IFERROR(--INDEX(Raw_Responses!$1:$1048576,0,MATCH($A3,Raw_Responses!$1:$1,0)),""))) -> 1 | E3: =IF($A3="","",AVERAGE(IFERROR(--INDEX(Raw_Responses!$1:$1048576,0,MATCH($A3,Raw_Responses!$1:$1,0)),""))) -> 0 | F3: =IF($A3="","",MEDIAN(IFERROR(--INDEX(Raw_Responses!$1:$1048576,0,MATCH($A3,Raw_Responses!$1:$1,0)),""))) -> 0 | G3: =IF($A3="","",IF($H3="","",SUMPRODUCT(--(INDEX(Raw_Responses!$1:$1048576,0,MATCH($A3,Raw_Responses!$1:$1,0))>=$H3))/COUNT(IFERROR(--INDEX(Raw_Responses!$1:$1048576,0,MATCH($A3,Raw_Responses!$1:$1,0)),"")))) -> 1 | H3: =IF($A3="","",IF(INDEX(Question_Map!$E$2:$E$100,2)=10,8,IF(INDEX(Question_Map!$E$2:$E$100,2)=5,4,INDEX(Question_Map!$E$2:$E$100,2)))) -> 8
A4: =IF(INDEX(Question_Map!$C$2:$C$100,3)="Scale",INDEX(Question_Map!$A$2:$A$100,3),"") -> The layout was easy to navigate. | B4: =IF($A4<>"",INDEX(Question_Map!$B$2:$B$100,3),"") -> NonTech | C4: =IF($A4<>"",INDEX(Question_Map!$F$2:$F$100,3),"") -> Navigation | D4: =IF($A4="","",COUNT(IFERROR(--INDEX(Raw_Responses!$1:$1048576,0,MATCH($A4,Raw_Responses!$1:$1,0)),""))) -> 1 | E4: =IF($A4="","",AVERAGE(IFERROR(--INDEX(Raw_Responses!$1:$1048576,0,MATCH($A4,Raw_Responses!$1:$1,0)),""))) -> 0 | F4: =IF($A4="","",MEDIAN(IFERROR(--INDEX(Raw_Responses!$1:$1048576,0,MATCH($A4,Raw_Responses!$1:$1,0)),""))) -> 0 | G4: =IF($A4="","",IF($H4="","",SUMPRODUCT(--(INDEX(Raw_Responses!$1:$1048576,0,MATCH($A4,Raw_Responses!$1:$1,0))>=$H4))/COUNT(IFERROR(--INDEX(Raw_Responses!$1:$1048576,0,MATCH($A4,Raw_Responses!$1:$1,0)),"")))) -> 1 | H4: =IF($A4="","",IF(INDEX(Question_Map!$E$2:$E$100,3)=10,8,IF(INDEX(Question_Map!$E$2:$E$100,3)=5,4,INDEX(Question_Map!$E$2:$E$100,3)))) -> 8
A5: =IF(INDEX(Question_Map!$C$2:$C$100,4)="Scale",INDEX(Question_Map!$A$2:$A$100,4),"") -> Pages loaded fast enough. | B5: =IF($A5<>"",INDEX(Question_Map!$B$2:$B$100,4),"") -> NonTech | C5: =IF($A5<>"",INDEX(Question_Map!$F$2:$F$100,4),"") -> Performance | D5: =IF($A5="","",COUNT(IFERROR(--INDEX(Raw_Responses!$1:$1048576,0,MATCH($A5,Raw_Responses!$1:$1,0)),""))) -> 1 | E5: =IF($A5="","",AVERAGE(IFERROR(--INDEX(Raw_Responses!$1:$1048576,0,MATCH($A5,Raw_Responses!$1:$1,0)),""))) -> 0 | F5: =IF($A5="","",MEDIAN(IFERROR(--INDEX(Raw_Responses!$1:$1048576,0,MATCH($A5,Raw_Responses!$1:$1,0)),""))) -> 0 | G5: =IF($A5="","",IF($H5="","",SUMPRODUCT(--(INDEX(Raw_Responses!$1:$1048576,0,MATCH($A5,Raw_Responses!$1:$1,0))>=$H5))/COUNT(IFERROR(--INDEX(Raw_Responses!$1:$1048576,0,MATCH($A5,Raw_Responses!$1:$1,0)),"")))) -> 1 | H5: =IF($A5="","",IF(INDEX(Question_Map!$E$2:$E$100,4)=10,8,IF(INDEX(Question_Map!$E$2:$E$100,4)=5,4,INDEX(Question_Map!$E$2:$E$100,4)))) -> 8
A6: =IF(INDEX(Question_Map!$C$2:$C$100,5)="Scale",INDEX(Question_Map!$A$2:$A$100,5),"") -> It worked comfortably on my phone/tablet. | B6: =IF($A6<>"",INDEX(Question_Map!$B$2:$B$100,5),"") -> NonTech | C6: =IF($A6<>"",INDEX(Question_Map!$F$2:$F$100,5),"") -> Accessibility | D6: =IF($A6="","",COUNT(IFERROR(--INDEX(Raw_Responses!$1:$1048576,0,MATCH($A6,Raw_Responses!$1:$1,0)),""))) -> 1 | E6: =IF($A6="","",AVERAGE(IFERROR(--INDEX(Raw_Responses!$1:$1048576,0,MATCH($A6,Raw_Responses!$1:$1,0)),""))) -> 0 | F6: =IF($A6="","",MEDIAN(IFERROR(--INDEX(Raw_Responses!$1:$1048576,0,MATCH($A6,Raw_Responses!$1:$1,0)),""))) -> 0 | G6: =IF($A6="","",IF($H6="","",SUMPRODUCT(--(INDEX(Raw_Responses!$1:$1048576,0,MATCH($A6,Raw_Responses!$1:$1,0))>=$H6))/COUNT(IFERROR(--INDEX(Raw_Responses!$1:$1048576,0,MATCH($A6,Raw_Responses!$1:$1,0)),"")))) -> 1 | H6: =IF($A6="","",IF(INDEX(Question_Map!$E$2:$E$100,5)=10,8,IF(INDEX(Question_Map!$E$2:$E$100,5)=5,4,INDEX(Question_Map!$E$2:$E$100,5)))) -> 8
A7: =IF(INDEX(Question_Map!$C$2:$C$100,6)="Scale",INDEX(Question_Map!$A$2:$A$100,6),"") -> Overall, it meets my needs. | B7: =IF($A7<>"",INDEX(Question_Map!$B$2:$B$100,6),"") -> NonTech | C7: =IF($A7<>"",INDEX(Question_Map!$F$2:$F$100,6),"") -> Satisfaction | D7: =IF($A7="","",COUNT(IFERROR(--INDEX(Raw_Responses!$1:$1048576,0,MATCH($A7,Raw_Responses!$1:$1,0)),""))) -> 1 | E7: =IF($A7="","",AVERAGE(IFERROR(--INDEX(Raw_Responses!$1:$1048576,0,MATCH($A7,Raw_Responses!$1:$1,0)),""))) -> 0 | F7: =IF($A7="","",MEDIAN(IFERROR(--INDEX(Raw_Responses!$1:$1048576,0,MATCH($A7,Raw_Responses!$1:$1,0)),""))) -> 0 | G7: =IF($A7="","",IF($H7="","",SUMPRODUCT(--(INDEX(Raw_Responses!$1:$1048576,0,MATCH($A7,Raw_Responses!$1:$1,0))>=$H7))/COUNT(IFERROR(--INDEX(Raw_Responses!$1:$1048576,0,MATCH($A7,Raw_Responses!$1:$1,0)),"")))) -> 1 | H7: =IF($A7="","",IF(INDEX(Question_Map!$E$2:$E$100,6)=10,8,IF(INDEX(Question_Map!$E$2:$E$100,6)=5,4,INDEX(Question_Map!$E$2:$E$100,6)))) -> 8
A8: =IF(INDEX(Question_Map!$C$2:$C$100,7)="Scale",INDEX(Question_Map!$A$2:$A$100,7),"") | B8: =IF($A8<>"",INDEX(Question_Map!$B$2:$B$100,7),"") | C8: =IF($A8<>"",INDEX(Question_Map!$F$2:$F$100,7),"") | D8: =IF($A8="","",COUNT(IFERROR(--INDEX(Raw_Responses!$1:$1048576,0,MATCH($A8,Raw_Responses!$1:$1,0)),""))) | E8: =IF($A8="","",AVERAGE(IFERROR(--INDEX(Raw_Responses!$1:$1048576,0,MATCH($A8,Raw_Responses!$1:$1,0)),""))) | F8: =IF($A8="","",MEDIAN(IFERROR(--INDEX(Raw_Responses!$1:$1048576,0,MATCH($A8,Raw_Responses!$1:$1,0)),""))) | G8: =IF($A8="","",IF($H8="","",SUMPRODUCT(--(INDEX(Raw_Responses!$1:$1048576,0,MATCH($A8,Raw_Responses!$1:$1,0))>=$H8))/COUNT(IFERROR(--INDEX(Raw_Responses!$1:$1048576,0,MATCH($A8,Raw_Responses!$1:$1,0)),"")))) | H8: =IF($A8="","",IF(INDEX(Question_Map!$E$2:$E$100,7)=10,8,IF(INDEX(Question_Map!$E$2:$E$100,7)=5,4,INDEX(Question_Map!$E$2:$E$100,7))))
A9: =IF(INDEX(Question_Map!$C$2:$C$100,8)="Scale",INDEX(Question_Map!$A$2:$A$100,8),"") | B9: =IF($A9<>"",INDEX(Question_Map!$B$2:$B$100,8),"") | C9: =IF($A9<>"",INDEX(Question_Map!$F$2:$F$100,8),"") | D9: =IF($A9="","",COUNT(IFERROR(--INDEX(Raw_Responses!$1:$1048576,0,MATCH($A9,Raw_Responses!$1:$1,0)),""))) | E9: =IF($A9="","",AVERAGE(IFERROR(--INDEX(Raw_Responses!$1:$1048576,0,MATCH($A9,Raw_Responses!$1:$1,0)),""))) | F9: =IF($A9="","",MEDIAN(IFERROR(--INDEX(Raw_Responses!$1:$1048576,0,MATCH($A9,Raw_Responses!$1:$1,0)),""))) | G9: =IF($A9="","",IF($H9="","",SUMPRODUCT(--(INDEX(Raw_Responses!$1:$1048576,0,MATCH($A9,Raw_Responses!$1:$1,0))>=$H9))/COUNT(IFERROR(--INDEX(Raw_Responses!$1:$1048576,0,MATCH($A9,Raw_Responses!$1:$1,0)),"")))) | H9: =IF($A9="","",IF(INDEX(Question_Map!$E$2:$E$100,8)=10,8,IF(INDEX(Question_Map!$E$2:$E$100,8)=5,4,INDEX(Question_Map!$E$2:$E$100,8))))
A10: =IF(INDEX(Question_Map!$C$2:$C$100,9)="Scale",INDEX(Question_Map!$A$2:$A$100,9),"") | B10: =IF($A10<>"",INDEX(Question_Map!$B$2:$B$100,9),"") | C10: =IF($A10<>"",INDEX(Question_Map!$F$2:$F$100,9),"") | D10: =IF($A10="","",COUNT(IFERROR(--INDEX(Raw_Responses!$1:$1048576,0,MATCH($A10,Raw_Responses!$1:$1,0)),""))) | E10: =IF($A10="","",AVERAGE(IFERROR(--INDEX(Raw_Responses!$1:$1048576,0,MATCH($A10,Raw_Responses!$1:$1,0)),""))) | F10: =IF($A10="","",MEDIAN(IFERROR(--INDEX(Raw_Responses!$1:$1048576,0,MATCH($A10,Raw_Responses!$1:$1,0)),""))) | G10: =IF($A10="","",IF($H10="","",SUMPRODUCT(--(INDEX(Raw_Responses!$1:$1048576,0,MATCH($A10,Raw_Responses!$1:$1,0))>=$H10))/COUNT(IFERROR(--INDEX(Raw_Responses!$1:$1048576,0,MATCH($A10,Raw_Responses!$1:$1,0)),"")))) | H10: =IF($A10="","",IF(INDEX(Question_Map!$E$2:$E$100,9)=10,8,IF(INDEX(Question_Map!$E$2:$E$100,9)=5,4,INDEX(Question_Map!$E$2:$E$100,9))))
A11: =IF(INDEX(Question_Map!$C$2:$C$100,10)="Scale",INDEX(Question_Map!$A$2:$A$100,10),"") | B11: =IF($A11<>"",INDEX(Question_Map!$B$2:$B$100,10),"") | C11: =IF($A11<>"",INDEX(Question_Map!$F$2:$F$100,10),"") | D11: =IF($A11="","",COUNT(IFERROR(--INDEX(Raw_Responses!$1:$1048576,0,MATCH($A11,Raw_Responses!$1:$1,0)),""))) | E11: =IF($A11="","",AVERAGE(IFERROR(--INDEX(Raw_Responses!$1:$1048576,0,MATCH($A11,Raw_Responses!$1:$1,0)),""))) | F11: =IF($A11="","",MEDIAN(IFERROR(--INDEX(Raw_Responses!$1:$1048576,0,MATCH($A11,Raw_Responses!$1:$1,0)),""))) | G11: =IF($A11="","",IF($H11="","",SUMPRODUCT(--(INDEX(Raw_Responses!$1:$1048576,0,MATCH($A11,Raw_Responses!$1:$1,0))>=$H11))/COUNT(IFERROR(--INDEX(Raw_Responses!$1:$1048576,0,MATCH($A11,Raw_Responses!$1:$1,0)),"")))) | H11: =IF($A11="","",IF(INDEX(Question_Map!$E$2:$E$100,10)=10,8,IF(INDEX(Question_Map!$E$2:$E$100,10)=5,4,INDEX(Question_Map!$E$2:$E$100,10))))
A12: =IF(INDEX(Question_Map!$C$2:$C$100,11)="Scale",INDEX(Question_Map!$A$2:$A$100,11),"") | B12: =IF($A12<>"",INDEX(Question_Map!$B$2:$B$100,11),"") | C12: =IF($A12<>"",INDEX(Question_Map!$F$2:$F$100,11),"") | D12: =IF($A12="","",COUNT(IFERROR(--INDEX(Raw_Responses!$1:$1048576,0,MATCH($A12,Raw_Responses!$1:$1,0)),""))) | E12: =IF($A12="","",AVERAGE(IFERROR(--INDEX(Raw_Responses!$1:$1048576,0,MATCH($A12,Raw_Responses!$1:$1,0)),""))) | F12: =IF($A12="","",MEDIAN(IFERROR(--INDEX(Raw_Responses!$1:$1048576,0,MATCH($A12,Raw_Responses!$1:$1,0)),""))) | G12: =IF($A12="","",IF($H12="","",SUMPRODUCT(--(INDEX(Raw_Responses!$1:$1048576,0,MATCH($A12,Raw_Responses!$1:$1,0))>=$H12))/COUNT(IFERROR(--INDEX(Raw_Responses!$1:$1048576,0,MATCH($A12,Raw_Responses!$1:$1,0)),"")))) | H12: =IF($A12="","",IF(INDEX(Question_Map!$E$2:$E$100,11)=10,8,IF(INDEX(Question_Map!$E$2:$E$100,11)=5,4,INDEX(Question_Map!$E$2:$E$100,11))))
A13: =IF(INDEX(Question_Map!$C$2:$C$100,12)="Scale",INDEX(Question_Map!$A$2:$A$100,12),"") | B13: =IF($A13<>"",INDEX(Question_Map!$B$2:$B$100,12),"") | C13: =IF($A13<>"",INDEX(Question_Map!$F$2:$F$100,12),"") | D13: =IF($A13="","",COUNT(IFERROR(--INDEX(Raw_Responses!$1:$1048576,0,MATCH($A13,Raw_Responses!$1:$1,0)),""))) | E13: =IF($A13="","",AVERAGE(IFERROR(--INDEX(Raw_Responses!$1:$1048576,0,MATCH($A13,Raw_Responses!$1:$1,0)),""))) | F13: =IF($A13="","",MEDIAN(IFERROR(--INDEX(Raw_Responses!$1:$1048576,0,MATCH($A13,Raw_Responses!$1:$1,0)),""))) | G13: =IF($A13="","",IF($H13="","",SUMPRODUCT(--(INDEX(Raw_Responses!$1:$1048576,0,MATCH($A13,Raw_Responses!$1:$1,0))>=$H13))/COUNT(IFERROR(--INDEX(Raw_Responses!$1:$1048576,0,MATCH($A13,Raw_Responses!$1:$1,0)),"")))) | H13: =IF($A13="","",IF(INDEX(Question_Map!$E$2:$E$100,12)=10,8,IF(INDEX(Question_Map!$E$2:$E$100,12)=5,4,INDEX(Question_Map!$E$2:$E$100,12))))
A14: =IF(INDEX(Question_Map!$C$2:$C$100,13)="Scale",INDEX(Question_Map!$A$2:$A$100,13),"") | B14: =IF($A14<>"",INDEX(Question_Map!$B$2:$B$100,13),"") | C14: =IF($A14<>"",INDEX(Question_Map!$F$2:$F$100,13),"") | D14: =IF($A14="","",COUNT(IFERROR(--INDEX(Raw_Responses!$1:$1048576,0,MATCH($A14,Raw_Responses!$1:$1,0)),""))) | E14: =IF($A14="","",AVERAGE(IFERROR(--INDEX(Raw_Responses!$1:$1048576,0,MATCH($A14,Raw_Responses!$1:$1,0)),""))) | F14: =IF($A14="","",MEDIAN(IFERROR(--INDEX(Raw_Responses!$1:$1048576,0,MATCH($A14,Raw_Responses!$1:$1,0)),""))) | G14: =IF($A14="","",IF($H14="","",SUMPRODUCT(--(INDEX(Raw_Responses!$1:$1048576,0,MATCH($A14,Raw_Responses!$1:$1,0))>=$H14))/COUNT(IFERROR(--INDEX(Raw_Responses!$1:$1048576,0,MATCH($A14,Raw_Responses!$1:$1,0)),"")))) | H14: =IF($A14="","",IF(INDEX(Question_Map!$E$2:$E$100,13)=10,8,IF(INDEX(Question_Map!$E$2:$E$100,13)=5,4,INDEX(Question_Map!$E$2:$E$100,13))))
A15: =IF(INDEX(Question_Map!$C$2:$C$100,14)="Scale",INDEX(Question_Map!$A$2:$A$100,14),"") | B15: =IF($A15<>"",INDEX(Question_Map!$B$2:$B$100,14),"") | C15: =IF($A15<>"",INDEX(Question_Map!$F$2:$F$100,14),"") | D15: =IF($A15="","",COUNT(IFERROR(--INDEX(Raw_Responses!$1:$1048576,0,MATCH($A15,Raw_Responses!$1:$1,0)),""))) | E15: =IF($A15="","",AVERAGE(IFERROR(--INDEX(Raw_Responses!$1:$1048576,0,MATCH($A15,Raw_Responses!$1:$1,0)),""))) | F15: =IF($A15="","",MEDIAN(IFERROR(--INDEX(Raw_Responses!$1:$1048576,0,MATCH($A15,Raw_Responses!$1:$1,0)),""))) | G15: =IF($A15="","",IF($H15="","",SUMPRODUCT(--(INDEX(Raw_Responses!$1:$1048576,0,MATCH($A15,Raw_Responses!$1:$1,0))>=$H15))/COUNT(IFERROR(--INDEX(Raw_Responses!$1:$1048576,0,MATCH($A15,Raw_Responses!$1:$1,0)),"")))) | H15: =IF($A15="","",IF(INDEX(Question_Map!$E$2:$E$100,14)=10,8,IF(INDEX(Question_Map!$E$2:$E$100,14)=5,4,INDEX(Question_Map!$E$2:$E$100,14))))
A16: =IF(INDEX(Question_Map!$C$2:$C$100,15)="Scale",INDEX(Question_Map!$A$2:$A$100,15),"") | B16: =IF($A16<>"",INDEX(Question_Map!$B$2:$B$100,15),"") | C16: =IF($A16<>"",INDEX(Question_Map!$F$2:$F$100,15),"") | D16: =IF($A16="","",COUNT(IFERROR(--INDEX(Raw_Responses!$1:$1048576,0,MATCH($A16,Raw_Responses!$1:$1,0)),""))) | E16: =IF($A16="","",AVERAGE(IFERROR(--INDEX(Raw_Responses!$1:$1048576,0,MATCH($A16,Raw_Responses!$1:$1,0)),""))) | F16: =IF($A16="","",MEDIAN(IFERROR(--INDEX(Raw_Responses!$1:$1048576,0,MATCH($A16,Raw_Responses!$1:$1,0)),""))) | G16: =IF($A16="","",IF($H16="","",SUMPRODUCT(--(INDEX(Raw_Responses!$1:$1048576,0,MATCH($A16,Raw_Responses!$1:$1,0))>=$H16))/COUNT(IFERROR(--INDEX(Raw_Responses!$1:$1048576,0,MATCH($A16,Raw_Responses!$1:$1,0)),"")))) | H16: =IF($A16="","",IF(INDEX(Question_Map!$E$2:$E$100,15)=10,8,IF(INDEX(Question_Map!$E$2:$E$100,15)=5,4,INDEX(Question_Map!$E$2:$E$100,15))))
A17: =IF(INDEX(Question_Map!$C$2:$C$100,16)="Scale",INDEX(Question_Map!$A$2:$A$100,16),"") | B17: =IF($A17<>"",INDEX(Question_Map!$B$2:$B$100,16),"") | C17: =IF($A17<>"",INDEX(Question_Map!$F$2:$F$100,16),"") | D17: =IF($A17="","",COUNT(IFERROR(--INDEX(Raw_Responses!$1:$1048576,0,MATCH($A17,Raw_Responses!$1:$1,0)),""))) | E17: =IF($A17="","",AVERAGE(IFERROR(--INDEX(Raw_Responses!$1:$1048576,0,MATCH($A17,Raw_Responses!$1:$1,0)),""))) | F17: =IF($A17="","",MEDIAN(IFERROR(--INDEX(Raw_Responses!$1:$1048576,0,MATCH($A17,Raw_Responses!$1:$1,0)),""))) | G17: =IF($A17="","",IF($H17="","",SUMPRODUCT(--(INDEX(Raw_Responses!$1:$1048576,0,MATCH($A17,Raw_Responses!$1:$1,0))>=$H17))/COUNT(IFERROR(--INDEX(Raw_Responses!$1:$1048576,0,MATCH($A17,Raw_Responses!$1:$1,0)),"")))) | H17: =IF($A17="","",IF(INDEX(Question_Map!$E$2:$E$100,16)=10,8,IF(INDEX(Question_Map!$E$2:$E$100,16)=5,4,INDEX(Question_Map!$E$2:$E$100,16))))
A18: =IF(INDEX(Question_Map!$C$2:$C$100,17)="Scale",INDEX(Question_Map!$A$2:$A$100,17),"") | B18: =IF($A18<>"",INDEX(Question_Map!$B$2:$B$100,17),"") | C18: =IF($A18<>"",INDEX(Question_Map!$F$2:$F$100,17),"") | D18: =IF($A18="","",COUNT(IFERROR(--INDEX(Raw_Responses!$1:$1048576,0,MATCH($A18,Raw_Responses!$1:$1,0)),""))) | E18: =IF($A18="","",AVERAGE(IFERROR(--INDEX(Raw_Responses!$1:$1048576,0,MATCH($A18,Raw_Responses!$1:$1,0)),""))) | F18: =IF($A18="","",MEDIAN(IFERROR(--INDEX(Raw_Responses!$1:$1048576,0,MATCH($A18,Raw_Responses!$1:$1,0)),""))) | G18: =IF($A18="","",IF($H18="","",SUMPRODUCT(--(INDEX(Raw_Responses!$1:$1048576,0,MATCH($A18,Raw_Responses!$1:$1,0))>=$H18))/COUNT(IFERROR(--INDEX(Raw_Responses!$1:$1048576,0,MATCH($A18,Raw_Responses!$1:$1,0)),"")))) | H18: =IF($A18="","",IF(INDEX(Question_Map!$E$2:$E$100,17)=10,8,IF(INDEX(Question_Map!$E$2:$E$100,17)=5,4,INDEX(Question_Map!$E$2:$E$100,17))))
A19: =IF(INDEX(Question_Map!$C$2:$C$100,18)="Scale",INDEX(Question_Map!$A$2:$A$100,18),"") | B19: =IF($A19<>"",INDEX(Question_Map!$B$2:$B$100,18),"") | C19: =IF($A19<>"",INDEX(Question_Map!$F$2:$F$100,18),"") | D19: =IF($A19="","",COUNT(IFERROR(--INDEX(Raw_Responses!$1:$1048576,0,MATCH($A19,Raw_Responses!$1:$1,0)),""))) | E19: =IF($A19="","",AVERAGE(IFERROR(--INDEX(Raw_Responses!$1:$1048576,0,MATCH($A19,Raw_Responses!$1:$1,0)),""))) | F19: =IF($A19="","",MEDIAN(IFERROR(--INDEX(Raw_Responses!$1:$1048576,0,MATCH($A19,Raw_Responses!$1:$1,0)),""))) | G19: =IF($A19="","",IF($H19="","",SUMPRODUCT(--(INDEX(Raw_Responses!$1:$1048576,0,MATCH($A19,Raw_Responses!$1:$1,0))>=$H19))/COUNT(IFERROR(--INDEX(Raw_Responses!$1:$1048576,0,MATCH($A19,Raw_Responses!$1:$1,0)),"")))) | H19: =IF($A19="","",IF(INDEX(Question_Map!$E$2:$E$100,18)=10,8,IF(INDEX(Question_Map!$E$2:$E$100,18)=5,4,INDEX(Question_Map!$E$2:$E$100,18))))
A20: =IF(INDEX(Question_Map!$C$2:$C$100,19)="Scale",INDEX(Question_Map!$A$2:$A$100,19),"") | B20: =IF($A20<>"",INDEX(Question_Map!$B$2:$B$100,19),"") | C20: =IF($A20<>"",INDEX(Question_Map!$F$2:$F$100,19),"") | D20: =IF($A20="","",COUNT(IFERROR(--INDEX(Raw_Responses!$1:$1048576,0,MATCH($A20,Raw_Responses!$1:$1,0)),""))) | E20: =IF($A20="","",AVERAGE(IFERROR(--INDEX(Raw_Responses!$1:$1048576,0,MATCH($A20,Raw_Responses!$1:$1,0)),""))) | F20: =IF($A20="","",MEDIAN(IFERROR(--INDEX(Raw_Responses!$1:$1048576,0,MATCH($A20,Raw_Responses!$1:$1,0)),""))) | G20: =IF($A20="","",IF($H20="","",SUMPRODUCT(--(INDEX(Raw_Responses!$1:$1048576,0,MATCH($A20,Raw_Responses!$1:$1,0))>=$H20))/COUNT(IFERROR(--INDEX(Raw_Responses!$1:$1048576,0,MATCH($A20,Raw_Responses!$1:$1,0)),"")))) | H20: =IF($A20="","",IF(INDEX(Question_Map!$E$2:$E$100,19)=10,8,IF(INDEX(Question_Map!$E$2:$E$100,19)=5,4,INDEX(Question_Map!$E$2:$E$100,19))))
A21: =IF(INDEX(Question_Map!$C$2:$C$100,20)="Scale",INDEX(Question_Map!$A$2:$A$100,20),"") | B21: =IF($A21<>"",INDEX(Question_Map!$B$2:$B$100,20),"") | C21: =IF($A21<>"",INDEX(Question_Map!$F$2:$F$100,20),"") | D21: =IF($A21="","",COUNT(IFERROR(--INDEX(Raw_Responses!$1:$1048576,0,MATCH($A21,Raw_Responses!$1:$1,0)),""))) | E21: =IF($A21="","",AVERAGE(IFERROR(--INDEX(Raw_Responses!$1:$1048576,0,MATCH($A21,Raw_Responses!$1:$1,0)),""))) | F21: =IF($A21="","",MEDIAN(IFERROR(--INDEX(Raw_Responses!$1:$1048576,0,MATCH($A21,Raw_Responses!$1:$1,0)),""))) | G21: =IF($A21="","",IF($H21="","",SUMPRODUCT(--(INDEX(Raw_Responses!$1:$1048576,0,MATCH($A21,Raw_Responses!$1:$1,0))>=$H21))/COUNT(IFERROR(--INDEX(Raw_Responses!$1:$1048576,0,MATCH($A21,Raw_Responses!$1:$1,0)),"")))) | H21: =IF($A21="","",IF(INDEX(Question_Map!$E$2:$E$100,20)=10,8,IF(INDEX(Question_Map!$E$2:$E$100,20)=5,4,INDEX(Question_Map!$E$2:$E$100,20))))
A22: =IF(INDEX(Question_Map!$C$2:$C$100,21)="Scale",INDEX(Question_Map!$A$2:$A$100,21),"") | B22: =IF($A22<>"",INDEX(Question_Map!$B$2:$B$100,21),"") | C22: =IF($A22<>"",INDEX(Question_Map!$F$2:$F$100,21),"") | D22: =IF($A22="","",COUNT(IFERROR(--INDEX(Raw_Responses!$1:$1048576,0,MATCH($A22,Raw_Responses!$1:$1,0)),""))) | E22: =IF($A22="","",AVERAGE(IFERROR(--INDEX(Raw_Responses!$1:$1048576,0,MATCH($A22,Raw_Responses!$1:$1,0)),""))) | F22: =IF($A22="","",MEDIAN(IFERROR(--INDEX(Raw_Responses!$1:$1048576,0,MATCH($A22,Raw_Responses!$1:$1,0)),""))) | G22: =IF($A22="","",IF($H22="","",SUMPRODUCT(--(INDEX(Raw_Responses!$1:$1048576,0,MATCH($A22,Raw_Responses!$1:$1,0))>=$H22))/COUNT(IFERROR(--INDEX(Raw_Responses!$1:$1048576,0,MATCH($A22,Raw_Responses!$1:$1,0)),"")))) | H22: =IF($A22="","",IF(INDEX(Question_Map!$E$2:$E$100,21)=10,8,IF(INDEX(Question_Map!$E$2:$E$100,21)=5,4,INDEX(Question_Map!$E$2:$E$100,21))))
A23: =IF(INDEX(Question_Map!$C$2:$C$100,22)="Scale",INDEX(Question_Map!$A$2:$A$100,22),"") | B23: =IF($A23<>"",INDEX(Question_Map!$B$2:$B$100,22),"") | C23: =IF($A23<>"",INDEX(Question_Map!$F$2:$F$100,22),"") | D23: =IF($A23="","",COUNT(IFERROR(--INDEX(Raw_Responses!$1:$1048576,0,MATCH($A23,Raw_Responses!$1:$1,0)),""))) | E23: =IF($A23="","",AVERAGE(IFERROR(--INDEX(Raw_Responses!$1:$1048576,0,MATCH($A23,Raw_Responses!$1:$1,0)),""))) | F23: =IF($A23="","",MEDIAN(IFERROR(--INDEX(Raw_Responses!$1:$1048576,0,MATCH($A23,Raw_Responses!$1:$1,0)),""))) | G23: =IF($A23="","",IF($H23="","",SUMPRODUCT(--(INDEX(Raw_Responses!$1:$1048576,0,MATCH($A23,Raw_Responses!$1:$1,0))>=$H23))/COUNT(IFERROR(--INDEX(Raw_Responses!$1:$1048576,0,MATCH($A23,Raw_Responses!$1:$1,0)),"")))) | H23: =IF($A23="","",IF(INDEX(Question_Map!$E$2:$E$100,22)=10,8,IF(INDEX(Question_Map!$E$2:$E$100,22)=5,4,INDEX(Question_Map!$E$2:$E$100,22))))
A24: =IF(INDEX(Question_Map!$C$2:$C$100,23)="Scale",INDEX(Question_Map!$A$2:$A$100,23),"") | B24: =IF($A24<>"",INDEX(Question_Map!$B$2:$B$100,23),"") | C24: =IF($A24<>"",INDEX(Question_Map!$F$2:$F$100,23),"") | D24: =IF($A24="","",COUNT(IFERROR(--INDEX(Raw_Responses!$1:$1048576,0,MATCH($A24,Raw_Responses!$1:$1,0)),""))) | E24: =IF($A24="","",AVERAGE(IFERROR(--INDEX(Raw_Responses!$1:$1048576,0,MATCH($A24,Raw_Responses!$1:$1,0)),""))) | F24: =IF($A24="","",MEDIAN(IFERROR(--INDEX(Raw_Responses!$1:$1048576,0,MATCH($A24,Raw_Responses!$1:$1,0)),""))) | G24: =IF($A24="","",IF($H24="","",SUMPRODUCT(--(INDEX(Raw_Responses!$1:$1048576,0,MATCH($A24,Raw_Responses!$1:$1,0))>=$H24))/COUNT(IFERROR(--INDEX(Raw_Responses!$1:$1048576,0,MATCH($A24,Raw_Responses!$1:$1,0)),"")))) | H24: =IF($A24="","",IF(INDEX(Question_Map!$E$2:$E$100,23)=10,8,IF(INDEX(Question_Map!$E$2:$E$100,23)=5,4,INDEX(Question_Map!$E$2:$E$100,23))))
A25: =IF(INDEX(Question_Map!$C$2:$C$100,24)="Scale",INDEX(Question_Map!$A$2:$A$100,24),"") | B25: =IF($A25<>"",INDEX(Question_Map!$B$2:$B$100,24),"") | C25: =IF($A25<>"",INDEX(Question_Map!$F$2:$F$100,24),"") | D25: =IF($A25="","",COUNT(IFERROR(--INDEX(Raw_Responses!$1:$1048576,0,MATCH($A25,Raw_Responses!$1:$1,0)),""))) | E25: =IF($A25="","",AVERAGE(IFERROR(--INDEX(Raw_Responses!$1:$1048576,0,MATCH($A25,Raw_Responses!$1:$1,0)),""))) | F25: =IF($A25="","",MEDIAN(IFERROR(--INDEX(Raw_Responses!$1:$1048576,0,MATCH($A25,Raw_Responses!$1:$1,0)),""))) | G25: =IF($A25="","",IF($H25="","",SUMPRODUCT(--(INDEX(Raw_Responses!$1:$1048576,0,MATCH($A25,Raw_Responses!$1:$1,0))>=$H25))/COUNT(IFERROR(--INDEX(Raw_Responses!$1:$1048576,0,MATCH($A25,Raw_Responses!$1:$1,0)),"")))) | H25: =IF($A25="","",IF(INDEX(Question_Map!$E$2:$E$100,24)=10,8,IF(INDEX(Question_Map!$E$2:$E$100,24)=5,4,INDEX(Question_Map!$E$2:$E$100,24))))
A26: =IF(INDEX(Question_Map!$C$2:$C$100,25)="Scale",INDEX(Question_Map!$A$2:$A$100,25),"") | B26: =IF($A26<>"",INDEX(Question_Map!$B$2:$B$100,25),"") | C26: =IF($A26<>"",INDEX(Question_Map!$F$2:$F$100,25),"") | D26: =IF($A26="","",COUNT(IFERROR(--INDEX(Raw_Responses!$1:$1048576,0,MATCH($A26,Raw_Responses!$1:$1,0)),""))) | E26: =IF($A26="","",AVERAGE(IFERROR(--INDEX(Raw_Responses!$1:$1048576,0,MATCH($A26,Raw_Responses!$1:$1,0)),""))) | F26: =IF($A26="","",MEDIAN(IFERROR(--INDEX(Raw_Responses!$1:$1048576,0,MATCH($A26,Raw_Responses!$1:$1,0)),""))) | G26: =IF($A26="","",IF($H26="","",SUMPRODUCT(--(INDEX(Raw_Responses!$1:$1048576,0,MATCH($A26,Raw_Responses!$1:$1,0))>=$H26))/COUNT(IFERROR(--INDEX(Raw_Responses!$1:$1048576,0,MATCH($A26,Raw_Responses!$1:$1,0)),"")))) | H26: =IF($A26="","",IF(INDEX(Question_Map!$E$2:$E$100,25)=10,8,IF(INDEX(Question_Map!$E$2:$E$100,25)=5,4,INDEX(Question_Map!$E$2:$E$100,25))))
A27: =IF(INDEX(Question_Map!$C$2:$C$100,26)="Scale",INDEX(Question_Map!$A$2:$A$100,26),"") | B27: =IF($A27<>"",INDEX(Question_Map!$B$2:$B$100,26),"") | C27: =IF($A27<>"",INDEX(Question_Map!$F$2:$F$100,26),"") | D27: =IF($A27="","",COUNT(IFERROR(--INDEX(Raw_Responses!$1:$1048576,0,MATCH($A27,Raw_Responses!$1:$1,0)),""))) | E27: =IF($A27="","",AVERAGE(IFERROR(--INDEX(Raw_Responses!$1:$1048576,0,MATCH($A27,Raw_Responses!$1:$1,0)),""))) | F27: =IF($A27="","",MEDIAN(IFERROR(--INDEX(Raw_Responses!$1:$1048576,0,MATCH($A27,Raw_Responses!$1:$1,0)),""))) | G27: =IF($A27="","",IF($H27="","",SUMPRODUCT(--(INDEX(Raw_Responses!$1:$1048576,0,MATCH($A27,Raw_Responses!$1:$1,0))>=$H27))/COUNT(IFERROR(--INDEX(Raw_Responses!$1:$1048576,0,MATCH($A27,Raw_Responses!$1:$1,0)),"")))) | H27: =IF($A27="","",IF(INDEX(Question_Map!$E$2:$E$100,26)=10,8,IF(INDEX(Question_Map!$E$2:$E$100,26)=5,4,INDEX(Question_Map!$E$2:$E$100,26))))
A28: =IF(INDEX(Question_Map!$C$2:$C$100,27)="Scale",INDEX(Question_Map!$A$2:$A$100,27),"") | B28: =IF($A28<>"",INDEX(Question_Map!$B$2:$B$100,27),"") | C28: =IF($A28<>"",INDEX(Question_Map!$F$2:$F$100,27),"") | D28: =IF($A28="","",COUNT(IFERROR(--INDEX(Raw_Responses!$1:$1048576,0,MATCH($A28,Raw_Responses!$1:$1,0)),""))) | E28: =IF($A28="","",AVERAGE(IFERROR(--INDEX(Raw_Responses!$1:$1048576,0,MATCH($A28,Raw_Responses!$1:$1,0)),""))) | F28: =IF($A28="","",MEDIAN(IFERROR(--INDEX(Raw_Responses!$1:$1048576,0,MATCH($A28,Raw_Responses!$1:$1,0)),""))) | G28: =IF($A28="","",IF($H28="","",SUMPRODUCT(--(INDEX(Raw_Responses!$1:$1048576,0,MATCH($A28,Raw_Responses!$1:$1,0))>=$H28))/COUNT(IFERROR(--INDEX(Raw_Responses!$1:$1048576,0,MATCH($A28,Raw_Responses!$1:$1,0)),"")))) | H28: =IF($A28="","",IF(INDEX(Question_Map!$E$2:$E$100,27)=10,8,IF(INDEX(Question_Map!$E$2:$E$100,27)=5,4,INDEX(Question_Map!$E$2:$E$100,27))))
A29: =IF(INDEX(Question_Map!$C$2:$C$100,28)="Scale",INDEX(Question_Map!$A$2:$A$100,28),"") | B29: =IF($A29<>"",INDEX(Question_Map!$B$2:$B$100,28),"") | C29: =IF($A29<>"",INDEX(Question_Map!$F$2:$F$100,28),"") | D29: =IF($A29="","",COUNT(IFERROR(--INDEX(Raw_Responses!$1:$1048576,0,MATCH($A29,Raw_Responses!$1:$1,0)),""))) | E29: =IF($A29="","",AVERAGE(IFERROR(--INDEX(Raw_Responses!$1:$1048576,0,MATCH($A29,Raw_Responses!$1:$1,0)),""))) | F29: =IF($A29="","",MEDIAN(IFERROR(--INDEX(Raw_Responses!$1:$1048576,0,MATCH($A29,Raw_Responses!$1:$1,0)),""))) | G29: =IF($A29="","",IF($H29="","",SUMPRODUCT(--(INDEX(Raw_Responses!$1:$1048576,0,MATCH($A29,Raw_Responses!$1:$1,0))>=$H29))/COUNT(IFERROR(--INDEX(Raw_Responses!$1:$1048576,0,MATCH($A29,Raw_Responses!$1:$1,0)),"")))) | H29: =IF($A29="","",IF(INDEX(Question_Map!$E$2:$E$100,28)=10,8,IF(INDEX(Question_Map!$E$2:$E$100,28)=5,4,INDEX(Question_Map!$E$2:$E$100,28))))
A30: =IF(INDEX(Question_Map!$C$2:$C$100,29)="Scale",INDEX(Question_Map!$A$2:$A$100,29),"") | B30: =IF($A30<>"",INDEX(Question_Map!$B$2:$B$100,29),"") | C30: =IF($A30<>"",INDEX(Question_Map!$F$2:$F$100,29),"") | D30: =IF($A30="","",COUNT(IFERROR(--INDEX(Raw_Responses!$1:$1048576,0,MATCH($A30,Raw_Responses!$1:$1,0)),""))) | E30: =IF($A30="","",AVERAGE(IFERROR(--INDEX(Raw_Responses!$1:$1048576,0,MATCH($A30,Raw_Responses!$1:$1,0)),""))) | F30: =IF($A30="","",MEDIAN(IFERROR(--INDEX(Raw_Responses!$1:$1048576,0,MATCH($A30,Raw_Responses!$1:$1,0)),""))) | G30: =IF($A30="","",IF($H30="","",SUMPRODUCT(--(INDEX(Raw_Responses!$1:$1048576,0,MATCH($A30,Raw_Responses!$1:$1,0))>=$H30))/COUNT(IFERROR(--INDEX(Raw_Responses!$1:$1048576,0,MATCH($A30,Raw_Responses!$1:$1,0)),"")))) | H30: =IF($A30="","",IF(INDEX(Question_Map!$E$2:$E$100,29)=10,8,IF(INDEX(Question_Map!$E$2:$E$100,29)=5,4,INDEX(Question_Map!$E$2:$E$100,29))))
A31: =IF(INDEX(Question_Map!$C$2:$C$100,30)="Scale",INDEX(Question_Map!$A$2:$A$100,30),"") | B31: =IF($A31<>"",INDEX(Question_Map!$B$2:$B$100,30),"") | C31: =IF($A31<>"",INDEX(Question_Map!$F$2:$F$100,30),"") | D31: =IF($A31="","",COUNT(IFERROR(--INDEX(Raw_Responses!$1:$1048576,0,MATCH($A31,Raw_Responses!$1:$1,0)),""))) | E31: =IF($A31="","",AVERAGE(IFERROR(--INDEX(Raw_Responses!$1:$1048576,0,MATCH($A31,Raw_Responses!$1:$1,0)),""))) | F31: =IF($A31="","",MEDIAN(IFERROR(--INDEX(Raw_Responses!$1:$1048576,0,MATCH($A31,Raw_Responses!$1:$1,0)),""))) | G31: =IF($A31="","",IF($H31="","",SUMPRODUCT(--(INDEX(Raw_Responses!$1:$1048576,0,MATCH($A31,Raw_Responses!$1:$1,0))>=$H31))/COUNT(IFERROR(--INDEX(Raw_Responses!$1:$1048576,0,MATCH($A31,Raw_Responses!$1:$1,0)),"")))) | H31: =IF($A31="","",IF(INDEX(Question_Map!$E$2:$E$100,30)=10,8,IF(INDEX(Question_Map!$E$2:$E$100,30)=5,4,INDEX(Question_Map!$E$2:$E$100,30))))
A34: If averages show zeros, ensure your Excel supports dynamic arrays; otherwise, use Pivot Tables (see README).

Sheet Scale_Distribution
A1: Header | B1: Audience | C1: Type | D1: ScaleMin | E1: ScaleMax | F1: 1 | G1: 2 | H1: 3 | I1: 4 | J1: 5 | K1: 6 | L1: 7 | M1: 8 | N1: 9 | O1: 10
A2: =INDEX(Question_Map!$A$2:$A$100,1) -> I could complete the key tasks without help. | B2: =INDEX(Question_Map!$B$2:$B$100,1) -> NonTech | C2: =INDEX(Question_Map!$C$2:$C$100,1) -> Scale | D2: =INDEX(Question_Map!$D$2:$D$100,1) -> 1 | E2: =INDEX(Question_Map!$E$2:$E$100,1) -> 10 | F2: =IF($C2<>"Scale","",COUNTIF(INDEX(Raw_Responses!$1:$1048576,0,MATCH($A2,Raw_Responses!$1:$1,0)),1)) -> 0 | G2: =IF($C2<>"Scale","",COUNTIF(INDEX(Raw_Responses!$1:$1048576,0,MATCH($A2,Raw_Responses!$1:$1,0)),2)) -> 0 | H2: =IF($C2<>"Scale","",COUNTIF(INDEX(Raw_Responses!$1:$1048576,0,MATCH($A2,Raw_Responses!$1:$1,0)),3)) -> 0 | I2: =IF($C2<>"Scale","",COUNTIF(INDEX(Raw_Responses!$1:$1048576,0,MATCH($A2,Raw_Responses!$1:$1,0)),4)) -> 0 | J2: =IF($C2<>"Scale","",COUNTIF(INDEX(Raw_Responses!$1:$1048576,0,MATCH($A2,Raw_Responses!$1:$1,0)),5)) -> 0 | K2: =IF($C2<>"Scale","",COUNTIF(INDEX(Raw_Responses!$1:$1048576,0,MATCH($A2,Raw_Responses!$1:$1,0)),6)) -> 0 | L2: =IF($C2<>"Scale","",COUNTIF(INDEX(Raw_Responses!$1:$1048576,0,MATCH($A2,Raw_Responses!$1:$1,0)),7)) -> 0 | M2: =IF($C2<>"Scale","",COUNTIF(INDEX(Raw_Responses!$1:$1048576,0,MATCH($A2,Raw_Responses!$1:$1,0)),8)) -> 0 | N2: =IF($C2<>"Scale","",COUNTIF(INDEX(Raw_Responses!$1:$1048576,0,MATCH($A2,Raw_Responses!$1:$1,0)),9)) -> 0 | O2: =IF($C2<>"Scale","",COUNTIF(INDEX(Raw_Responses!$1:$1048576,0,MATCH($A2,Raw_Responses!$1:$1,0)),10)) -> 0
A3: =INDEX(Question_Map!$A$2:$A$100,2) -> Labels and buttons were clear. | B3: =INDEX(Question_Map!$B$2:$B$100,2) -> NonTech | C3: =INDEX(Question_Map!$C$2:$C$100,2) -> Scale | D3: =INDEX(Question_Map!$D$2:$D$100,2) -> 1 | E3: =INDEX(Question_Map!$E$2:$E$100,2) -> 10 | F3: =IF($C3<>"Scale","",COUNTIF(INDEX(Raw_Responses!$1:$1048576,0,MATCH($A3,Raw_Responses!$1:$1,0)),1)) -> 0 | G3: =IF($C3<>"Scale","",COUNTIF(INDEX(Raw_Responses!$1:$1048576,0,MATCH($A3,Raw_Responses!$1:$1,0)),2)) -> 0 | H3: =IF($C3<>"Scale","",COUNTIF(INDEX(Raw_Responses!$1:$1048576,0,MATCH($A3,Raw_Responses!$1:$1,0)),3)) -> 0 | I3: =IF($C3<>"Scale","",COUNTIF(INDEX(Raw_Responses!$1:$1048576,0,MATCH($A3,Raw_Responses!$1:$1,0)),4)) -> 0 | J3: =IF($C3<>"Scale","",COUNTIF(INDEX(Raw_Responses!$1:$1048576,0,MATCH($A3,Raw_Responses!$1:$1,0)),5)) -> 0 | K3: =IF($C3<>"Scale","",COUNTIF(INDEX(Raw_Responses!$1:$1048576,0,MATCH($A3,Raw_Responses!$1:$1,0)),6)) -> 0 | L3: =IF($C3<>"Scale","",COUNTIF(INDEX(Raw_Responses!$1:$1048576,0,MATCH($A3,Raw_Responses!$1:$1,0)),7)) -> 0 | M3: =IF($C3<>"Scale","",COUNTIF(INDEX(Raw_Responses!$1:$1048576,0,MATCH($A3,Raw_Responses!$1:$1,0)),8)) -> 0 | N3: =IF($C3<>"Scale","",COUNTIF(INDEX(Raw_Responses!$1:$1048576,0,MATCH($A3,Raw_Responses!$1:$1,0)),9)) -> 0 | O3: =IF($C3<>"Scale","",COUNTIF(INDEX(Raw_Responses!$1:$1048576,0,MATCH($A3,Raw_Responses!$1:$1,0)),10)) -> 0
A4: =INDEX(Question_Map!$A$2:$A$100,3) -> The layout was easy to navigate. | B4: =INDEX(Question_Map!$B$2:$B$100,3) -> NonTech | C4: =INDEX(Question_Map!$C$2:$C$100,3) -> Scale | D4: =INDEX(Question_Map!$D$2:$D$100,3) -> 1 | E4: =INDEX(Question_Map!$E$2:$E$100,3) -> 10 | F4: =IF($C4<>"Scale","",COUNTIF(INDEX(Raw_Responses!$1:$1048576,0,MATCH($A4,Raw_Responses!$1:$1,0)),1)) -> 0 | G4: =IF($C4<>"Scale","",COUNTIF(INDEX(Raw_Responses!$1:$1048576,0,MATCH($A4,Raw_Responses!$1:$1,0)),2)) -> 0 | H4: =IF($C4<>"Scale","",COUNTIF(INDEX(Raw_Responses!$1:$1048576,0,MATCH($A4,Raw_Responses!$1:$1,0)),3)) -> 0 | I4: =IF($C4<>"Scale","",COUNTIF(INDEX(Raw_Responses!$1:$1048576,0,MATCH($A4,Raw_Responses!$1:$1,0)),4)) -> 0 | J4: =IF($C4<>"Scale","",COUNTIF(INDEX(Raw_Responses!$1:$1048576,0,MATCH($A4,Raw_Responses!$1:$1,0)),5)) -> 0 | K4: =IF($C4<>"Scale","",COUNTIF(INDEX(Raw_Responses!$1:$1048576,0,MATCH($A4,Raw_Responses!$1:$1,0)),6)) -> 0 | L4: =IF($C4<>"Scale","",COUNTIF(INDEX(Raw_Responses!$1:$1048576,0,MATCH($A4,Raw_Responses!$1:$1,0)),7)) -> 0 | M4: =IF($C4<>"Scale","",COUNTIF(INDEX(Raw_Responses!$1:$1048576,0,MATCH($A4,Raw_Responses!$1:$1,0)),8)) -> 0 | N4: =IF($C4<>"Scale","",COUNTIF(INDEX(Raw_Responses!$1:$1048576,0,MATCH($A4,Raw_Responses!$1:$1,0)),9)) -> 0 | O4: =IF($C4<>"Scale","",COUNTIF(INDEX(Raw_Responses!$1:$1048576,0,MATCH($A4,Raw_Responses!$1:$1,0)),10)) -> 0
A5: =INDEX(Question_Map!$A$2:$A$100,4) -> Pages loaded fast enough. | B5: =INDEX(Question_Map!$B$2:$B$100,4) -> NonTech | C5: =INDEX(Question_Map!$C$2:$C$100,4) -> Scale | D5: =INDEX(Question_Map!$D$2:$D$100,4) -> 1 | E5: =INDEX(Question_Map!$E$2:$E$100,4) -> 10 | F5: =IF($C5<>"Scale","",COUNTIF(INDEX(Raw_Responses!$1:$1048576,0,MATCH($A5,Raw_Responses!$1:$1,0)),1)) -> 0 | G5: =IF($C5<>"Scale","",COUNTIF(INDEX(Raw_Responses!$1:$1048576,0,MATCH($A5,Raw_Responses!$1:$1,0)),2)) -> 0 | H5: =IF($C5<>"Scale","",COUNTIF(INDEX(Raw_Responses!$1:$1048576,0,MATCH($A5,Raw_Responses!$1:$1,0)),3)) -> 0 | I5: =IF($C5<>"Scale","",COUNTIF(INDEX(Raw_Responses!$1:$1048576,0,MATCH($A5,Raw_Responses!$1:$1,0)),4)) -> 0 | J5: =IF($C5<>"Scale","",COUNTIF(INDEX(Raw_Responses!$1:$1048576,0,MATCH($A5,Raw_Responses!$1:$1,0)),5)) -> 0 | K5: =IF($C5<>"Scale","",COUNTIF(INDEX(Raw_Responses!$1:$1048576,0,MATCH($A5,Raw_Responses!$1:$1,0)),6)) -> 0 | L5: =IF($C5<>"Scale","",COUNTIF(INDEX(Raw_Responses!$1:$1048576,0,MATCH($A5,Raw_Responses!$1:$1,0)),7)) -> 0 | M5: =IF($C5<>"Scale","",COUNTIF(INDEX(Raw_Responses!$1:$1048576,0,MATCH($A5,Raw_Responses!$1:$1,0)),8)) -> 0 | N5: =IF($C5<>"Scale","",COUNTIF(INDEX(Raw_Responses!$1:$1048576,0,MATCH($A5,Raw_Responses!$1:$1,0)),9)) -> 0 | O5: =IF($C5<>"Scale","",COUNTIF(INDEX(Raw_Responses!$1:$1048576,0,MATCH($A5,Raw_Responses!$1:$1,0)),10)) -> 0
A6: =INDEX(Question_Map!$A$2:$A$100,5) -> It worked comfortably on my phone/tablet. | B6: =INDEX(Question_Map!$B$2:$B$100,5) -> NonTech | C6: =INDEX(Question_Map!$C$2:$C$100,5) -> Scale | D6: =INDEX(Question_Map!$D$2:$D$100,5) -> 1 | E6: =INDEX(Question_Map!$E$2:$E$100,5) -> 10 | F6: =IF($C6<>"Scale","",COUNTIF(INDEX(Raw_Responses!$1:$1048576,0,MATCH($A6,Raw_Responses!$1:$1,0)),1)) -> 0 | G6: =IF($C6<>"Scale","",COUNTIF(INDEX(Raw_Responses!$1:$1048576,0,MATCH($A6,Raw_Responses!$1:$1,0)),2)) -> 0 | H6: =IF($C6<>"Scale","",COUNTIF(INDEX(Raw_Responses!$1:$1048576,0,MATCH($A6,Raw_Responses!$1:$1,0)),3)) -> 0 | I6: =IF($C6<>"Scale","",COUNTIF(INDEX(Raw_Responses!$1:$1048576,0,MATCH($A6,Raw_Responses!$1:$1,0)),4)) -> 0 | J6: =IF($C6<>"Scale","",COUNTIF(INDEX(Raw_Responses!$1:$1048576,0,MATCH($A6,Raw_Responses!$1:$1,0)),5)) -> 0 | K6: =IF($C6<>"Scale","",COUNTIF(INDEX(Raw_Responses!$1:$1048576,0,MATCH($A6,Raw_Responses!$1:$1,0)),6)) -> 0 | L6: =IF($C6<>"Scale","",COUNTIF(INDEX(Raw_Responses!$1:$1048576,0,MATCH($A6,Raw_Responses!$1:$1,0)),7)) -> 0 | M6: =IF($C6<>"Scale","",COUNTIF(INDEX(Raw_Responses!$1:$1048576,0,MATCH($A6,Raw_Responses!$1:$1,0)),8)) -> 0 | N6: =IF($C6<>"Scale","",COUNTIF(INDEX(Raw_Responses!$1:$1048576,0,MATCH($A6,Raw_Responses!$1:$1,0)),9)) -> 0 | O6: =IF($C6<>"Scale","",COUNTIF(INDEX(Raw_Responses!$1:$1048576,0,MATCH($A6,Raw_Responses!$1:$1,0)),10)) -> 0
A7: =INDEX(Question_Map!$A$2:$A$100,6) -> Overall, it meets my needs. | B7: =INDEX(Question_Map!$B$2:$B$100,6) -> NonTech | C7: =INDEX(Question_Map!$C$2:$C$100,6) -> Scale | D7: =INDEX(Question_Map!$D$2:$D$100,6) -> 1 | E7: =INDEX(Question_Map!$E$2:$E$100,6) -> 10 | F7: =IF($C7<>"Scale","",COUNTIF(INDEX(Raw_Responses!$1:$1048576,0,MATCH($A7,Raw_Responses!$1:$1,0)),1)) -> 0 | G7: =IF($C7<>"Scale","",COUNTIF(INDEX(Raw_Responses!$1:$1048576,0,MATCH($A7,Raw_Responses!$1:$1,0)),2)) -> 0 | H7: =IF($C7<>"Scale","",COUNTIF(INDEX(Raw_Responses!$1:$1048576,0,MATCH($A7,Raw_Responses!$1:$1,0)),3)) -> 0 | I7: =IF($C7<>"Scale","",COUNTIF(INDEX(Raw_Responses!$1:$1048576,0,MATCH($A7,Raw_Responses!$1:$1,0)),4)) -> 0 | J7: =IF($C7<>"Scale","",COUNTIF(INDEX(Raw_Responses!$1:$1048576,0,MATCH($A7,Raw_Responses!$1:$1,0)),5)) -> 0 | K7: =IF($C7<>"Scale","",COUNTIF(INDEX(Raw_Responses!$1:$1048576,0,MATCH($A7,Raw_Responses!$1:$1,0)),6)) -> 0 | L7: =IF($C7<>"Scale","",COUNTIF(INDEX(Raw_Responses!$1:$1048576,0,MATCH($A7,Raw_Responses!$1:$1,0)),7)) -> 0 | M7: =IF($C7<>"Scale","",COUNTIF(INDEX(Raw_Responses!$1:$1048576,0,MATCH($A7,Raw_Responses!$1:$1,0)),8)) -> 0 | N7: =IF($C7<>"Scale","",COUNTIF(INDEX(Raw_Responses!$1:$1048576,0,MATCH($A7,Raw_Responses!$1:$1,0)),9)) -> 0 | O7: =IF($C7<>"Scale","",COUNTIF(INDEX(Raw_Responses!$1:$1048576,0,MATCH($A7,Raw_Responses!$1:$1,0)),10)) -> 0
A8: =INDEX(Question_Map!$A$2:$A$100,7) -> Which feature was most useful? | B8: =INDEX(Question_Map!$B$2:$B$100,7) -> NonTech | C8: =INDEX(Question_Map!$C$2:$C$100,7) -> MCQ | D8: =INDEX(Question_Map!$D$2:$D$100,7) -> 0 | E8: =INDEX(Question_Map!$E$2:$E$100,7) -> 0 | F8: =IF($C8<>"Scale","",COUNTIF(INDEX(Raw_Responses!$1:$1048576,0,MATCH($A8,Raw_Responses!$1:$1,0)),1)) | G8: =IF($C8<>"Scale","",COUNTIF(INDEX(Raw_Responses!$1:$1048576,0,MATCH($A8,Raw_Responses!$1:$1,0)),2)) | H8: =IF($C8<>"Scale","",COUNTIF(INDEX(Raw_Responses!$1:$1048576,0,MATCH($A8,Raw_Responses!$1:$1,0)),3)) | I8: =IF($C8<>"Scale","",COUNTIF(INDEX(Raw_Responses!$1:$1048576,0,MATCH($A8,Raw_Responses!$1:$1,0)),4)) | J8: =IF($C8<>"Scale","",COUNTIF(INDEX(Raw_Responses!$1:$1048576,0,MATCH($A8,Raw_Responses!$1:$1,0)),5)) | K8: =IF($C8<>"Scale","",COUNTIF(INDEX(Raw_Responses!$1:$1048576,0,MATCH($A8,Raw_Responses!$1:$1,0)),6)) | L8: =IF($C8<>"Scale","",COUNTIF(INDEX(Raw_Responses!$1:$1048576,0,MATCH($A8,Raw_Responses!$1:$1,0)),7)) | M8: =IF($C8<>"Scale","",COUNTIF(INDEX(Raw_Responses!$1:$1048576,0,MATCH($A8,Raw_Responses!$1:$1,0)),8)) | N8: =IF($C8<>"Scale","",COUNTIF(INDEX(Raw_Responses!$1:$1048576,0,MATCH($A8,Raw_Responses!$1:$1,0)),9)) | O8: =IF($C8<>"Scale","",COUNTIF(INDEX(Raw_Responses!$1:$1048576,0,MATCH($A8,Raw_Responses!$1:$1,0)),10))
A9: =INDEX(Question_Map!$A$2:$A$100,8) -> What confused you or slowed you down and why? | B9: =INDEX(Question_Map!$B$2:$B$100,8) -> NonTech | C9: =INDEX(Question_Map!$C$2:$C$100,8) -> Text | D9: =INDEX(Question_Map!$D$2:$D$100,8) -> 0 | E9: =INDEX(Question_Map!$E$2:$E$100,8) -> 0 | F9: =IF($C9<>"Scale","",COUNTIF(INDEX(Raw_Responses!$1:$1048576,0,MATCH($A9,Raw_Responses!$1:$1,0)),1)) | G9: =IF($C9<>"Scale","",COUNTIF(INDEX(Raw_Responses!$1:$1048576,0,MATCH($A9,Raw_Responses!$1:$1,0)),2)) | H9: =IF($C9<>"Scale","",COUNTIF(INDEX(Raw_Responses!$1:$1048576,0,MATCH($A9,Raw_Responses!$1:$1,0)),3)) | I9: =IF($C9<>"Scale","",COUNTIF(INDEX(Raw_Responses!$1:$1048576,0,MATCH($A9,Raw_Responses!$1:$1,0)),4)) | J9: =IF($C9<>"Scale","",COUNTIF(INDEX(Raw_Responses!$1:$1048576,0,MATCH($A9,Raw_Responses!$1:$1,0)),5)) | K9: =IF($C9<>"Scale","",COUNTIF(INDEX(Raw_Responses!$1:$1048576,0,MATCH($A9,Raw_Responses!$1:$1,0)),6)) | L9: =IF($C9<>"Scale","",COUNTIF(INDEX(Raw_Responses!$1:$1048576,0,MATCH($A9,Raw_Responses!$1:$1,0)),7)) | M9: =IF($C9<>"Scale","",COUNTIF(INDEX(Raw_Responses!$1:$1048576,0,MATCH($A9,Raw_Responses!$1:$1,0)),8)) | N9: =IF($C9<>"Scale","",COUNTIF(INDEX(Raw_Responses!$1:$1048576,0,MATCH($A9,Raw_Responses!$1:$1,0)),9)) | O9: =IF($C9<>"Scale","",COUNTIF(INDEX(Raw_Responses!$1:$1048576,0,MATCH($A9,Raw_Responses!$1:$1,0)),10))
A10: =INDEX(Question_Map!$A$2:$A$100,9) -> Top 2 improvements you'd like next | B10: =INDEX(Question_Map!$B$2:$B$100,9) -> NonTech | C10: =INDEX(Question_Map!$C$2:$C$100,9) -> Text | D10: =INDEX(Question_Map!$D$2:$D$100,9) -> 0 | E10: =INDEX(Question_Map!$E$2:$E$100,9) -> 0 | F10: =IF($C10<>"Scale","",COUNTIF(INDEX(Raw_Responses!$1:$1048576,0,MATCH($A10,Raw_Responses!$1:$1,0)),1)) | G10: =IF($C10<>"Scale","",COUNTIF(INDEX(Raw_Responses!$1:$1048576,0,MATCH($A10,Raw_Responses!$1:$1,0)),2)) | H10: =IF($C10<>"Scale","",COUNTIF(INDEX(Raw_Responses!$1:$1048576,0,MATCH($A10,Raw_Responses!$1:$1,0)),3)) | I10: =IF($C10<>"Scale","",COUNTIF(INDEX(Raw_Responses!$1:$1048576,0,MATCH($A10,Raw_Responses!$1:$1,0)),4)) | J10: =IF($C10<>"Scale","",COUNTIF(INDEX(Raw_Responses!$1:$1048576,0,MATCH($A10,Raw_Responses!$1:$1,0)),5)) | K10: =IF($C10<>"Scale","",COUNTIF(INDEX(Raw_Responses!$1:$1048576,0,MATCH($A10,Raw_Responses!$1:$1,0)),6)) | L10: =IF($C10<>"Scale","",COUNTIF(INDEX(Raw_Responses!$1:$1048576,0,MATCH($A10,Raw_Responses!$1:$1,0)),7)) | M10: =IF($C10<>"Scale","",COUNTIF(INDEX(Raw_Responses!$1:$1048576,0,MATCH($A10,Raw_Responses!$1:$1,0)),8)) | N10: =IF($C10<>"Scale","",COUNTIF(INDEX(Raw_Responses!$1:$1048576,0,MATCH($A10,Raw_Responses!$1:$1,0)),9)) | O10: =IF($C10<>"Scale","",COUNTIF(INDEX(Raw_Responses!$1:$1048576,0,MATCH($A10,Raw_Responses!$1:$1,0)),10))
A11: =INDEX(Question_Map!$A$2:$A$100,10) -> Anything you liked that I should keep | B11: =INDEX(Question_Map!$B$2:$B$100,10) -> NonTech | C11: =INDEX(Question_Map!$C$2:$C$100,10) -> Text | D11: =INDEX(Question_Map!$D$2:$D$100,10) -> 0 | E11: =INDEX(Question_Map!$E$2:$E$100,10) -> 0 | F11: =IF($C11<>"Scale","",COUNTIF(INDEX(Raw_Responses!$1:$1048576,0,MATCH($A11,Raw_Responses!$1:$1,0)),1)) | G11: =IF($C11<>"Scale","",COUNTIF(INDEX(Raw_Responses!$1:$1048576,0,MATCH($A11,Raw_Responses!$1:$1,0)),2)) | H11: =IF($C11<>"Scale","",COUNTIF(INDEX(Raw_Responses!$1:$1048576,0,MATCH($A11,Raw_Responses!$1:$1,0)),3)) | I11: =IF($C11<>"Scale","",COUNTIF(INDEX(Raw_Responses!$1:$1048576,0,MATCH($A11,Raw_Responses!$1:$1,0)),4)) | J11: =IF($C11<>"Scale","",COUNTIF(INDEX(Raw_Responses!$1:$1048576,0,MATCH($A11,Raw_Responses!$1:$1,0)),5)) | K11: =IF($C11<>"Scale","",COUNTIF(INDEX(Raw_Responses!$1:$1048576,0,MATCH($A11,Raw_Responses!$1:$1,0)),6)) | L11: =IF($C11<>"Scale","",COUNTIF(INDEX(Raw_Responses!$1:$1048576,0,MATCH($A11,Raw_Responses!$1:$1,0)),7)) | M11: =IF($C11<>"Scale","",COUNTIF(INDEX(Raw_Responses!$1:$1048576,0,MATCH($A11,Raw_Responses!$1:$1,0)),8)) | N11: =IF($C11<>"Scale","",COUNTIF(INDEX(Raw_Responses!$1:$1048576,0,MATCH($A11,Raw_Responses!$1:$1,0)),9)) | O11: =IF($C11<>"Scale","",COUNTIF(INDEX(Raw_Responses!$1:$1048576,0,MATCH($A11,Raw_Responses!$1:$1,0)),10))
A12: =INDEX(Question_Map!$A$2:$A$100,11) -> 0 | B12: =INDEX(Question_Map!$B$2:$B$100,11) -> 0 | C12: =INDEX(Question_Map!$C$2:$C$100,11) -> 0 | D12: =INDEX(Question_Map!$D$2:$D$100,11) -> 0 | E12: =INDEX(Question_Map!$E$2:$E$100,11) -> 0 | F12: =IF($C12<>"Scale","",COUNTIF(INDEX(Raw_Responses!$1:$1048576,0,MATCH($A12,Raw_Responses!$1:$1,0)),1)) | G12: =IF($C12<>"Scale","",COUNTIF(INDEX(Raw_Responses!$1:$1048576,0,MATCH($A12,Raw_Responses!$1:$1,0)),2)) | H12: =IF($C12<>"Scale","",COUNTIF(INDEX(Raw_Responses!$1:$1048576,0,MATCH($A12,Raw_Responses!$1:$1,0)),3)) | I12: =IF($C12<>"Scale","",COUNTIF(INDEX(Raw_Responses!$1:$1048576,0,MATCH($A12,Raw_Responses!$1:$1,0)),4)) | J12: =IF($C12<>"Scale","",COUNTIF(INDEX(Raw_Responses!$1:$1048576,0,MATCH($A12,Raw_Responses!$1:$1,0)),5)) | K12: =IF($C12<>"Scale","",COUNTIF(INDEX(Raw_Responses!$1:$1048576,0,MATCH($A12,Raw_Responses!$1:$1,0)),6)) | L12: =IF($C12<>"Scale","",COUNTIF(INDEX(Raw_Responses!$1:$1048576,0,MATCH($A12,Raw_Responses!$1:$1,0)),7)) | M12: =IF($C12<>"Scale","",COUNTIF(INDEX(Raw_Responses!$1:$1048576,0,MATCH($A12,Raw_Responses!$1:$1,0)),8)) | N12: =IF($C12<>"Scale","",COUNTIF(INDEX(Raw_Responses!$1:$1048576,0,MATCH($A12,Raw_Responses!$1:$1,0)),9)) | O12: =IF($C12<>"Scale","",COUNTIF(INDEX(Raw_Responses!$1:$1048576,0,MATCH($A12,Raw_Responses!$1:$1,0)),10))
A13: =INDEX(Question_Map!$A$2:$A$100,12) -> 0 | B13: =INDEX(Question_Map!$B$2:$B$100,12) -> 0 | C13: =INDEX(Question_Map!$C$2:$C$100,12) -> 0 | D13: =INDEX(Question_Map!$D$2:$D$100,12) -> 0 | E13: =INDEX(Question_Map!$E$2:$E$100,12) -> 0 | F13: =IF($C13<>"Scale","",COUNTIF(INDEX(Raw_Responses!$1:$1048576,0,MATCH($A13,Raw_Responses!$1:$1,0)),1)) | G13: =IF($C13<>"Scale","",COUNTIF(INDEX(Raw_Responses!$1:$1048576,0,MATCH($A13,Raw_Responses!$1:$1,0)),2)) | H13: =IF($C13<>"Scale","",COUNTIF(INDEX(Raw_Responses!$1:$1048576,0,MATCH($A13,Raw_Responses!$1:$1,0)),3)) | I13: =IF($C13<>"Scale","",COUNTIF(INDEX(Raw_Responses!$1:$1048576,0,MATCH($A13,Raw_Responses!$1:$1,0)),4)) | J13: =IF($C13<>"Scale","",COUNTIF(INDEX(Raw_Responses!$1:$1048576,0,MATCH($A13,Raw_Responses!$1:$1,0)),5)) | K13: =IF($C13<>"Scale","",COUNTIF(INDEX(Raw_Responses!$1:$1048576,0,MATCH($A13,Raw_Responses!$1:$1,0)),6)) | L13: =IF($C13<>"Scale","",COUNTIF(INDEX(Raw_Responses!$1:$1048576,0,MATCH($A13,Raw_Responses!$1:$1,0)),7)) | M13: =IF($C13<>"Scale","",COUNTIF(INDEX(Raw_Responses!$1:$1048576,0,MATCH($A13,Raw_Responses!$1:$1,0)),8)) | N13: =IF($C13<>"Scale","",COUNTIF(INDEX(Raw_Responses!$1:$1048576,0,MATCH($A13,Raw_Responses!$1:$1,0)),9)) | O13: =IF($C13<>"Scale","",COUNTIF(INDEX(Raw_Responses!$1:$1048576,0,MATCH($A13,Raw_Responses!$1:$1,0)),10))
A14: =INDEX(Question_Map!$A$2:$A$100,13) -> 0 | B14: =INDEX(Question_Map!$B$2:$B$100,13) -> 0 | C14: =INDEX(Question_Map!$C$2:$C$100,13) -> 0 | D14: =INDEX(Question_Map!$D$2:$D$100,13) -> 0 | E14: =INDEX(Question_Map!$E$2:$E$100,13) -> 0 | F14: =IF($C14<>"Scale","",COUNTIF(INDEX(Raw_Responses!$1:$1048576,0,MATCH($A14,Raw_Responses!$1:$1,0)),1)) | G14: =IF($C14<>"Scale","",COUNTIF(INDEX(Raw_Responses!$1:$1048576,0,MATCH($A14,Raw_Responses!$1:$1,0)),2)) | H14: =IF($C14<>"Scale","",COUNTIF(INDEX(Raw_Responses!$1:$1048576,0,MATCH($A14,Raw_Responses!$1:$1,0)),3)) | I14: =IF($C14<>"Scale","",COUNTIF(INDEX(Raw_Responses!$1:$1048576,0,MATCH($A14,Raw_Responses!$1:$1,0)),4)) | J14: =IF($C14<>"Scale","",COUNTIF(INDEX(Raw_Responses!$1:$1048576,0,MATCH($A14,Raw_Responses!$1:$1,0)),5)) | K14: =IF($C14<>"Scale","",COUNTIF(INDEX(Raw_Responses!$1:$1048576,0,MATCH($A14,Raw_Responses!$1:$1,0)),6)) | L14: =IF($C14<>"Scale","",COUNTIF(INDEX(Raw_Responses!$1:$1048576,0,MATCH($A14,Raw_Responses!$1:$1,0)),7)) | M14: =IF($C14<>"Scale","",COUNTIF(INDEX(Raw_Responses!$1:$1048576,0,MATCH($A14,Raw_Responses!$1:$1,0)),8)) | N14: =IF($C14<>"Scale","",COUNTIF(INDEX(Raw_Responses!$1:$1048576,0,MATCH($A14,Raw_Responses!$1:$1,0)),9)) | O14: =IF($C14<>"Scale","",COUNTIF(INDEX(Raw_Responses!$1:$1048576,0,MATCH($A14,Raw_Responses!$1:$1,0)),10))
A15: =INDEX(Question_Map!$A$2:$A$100,14) -> 0 | B15: =INDEX(Question_Map!$B$2:$B$100,14) -> 0 | C15: =INDEX(Question_Map!$C$2:$C$100,14) -> 0 | D15: =INDEX(Question_Map!$D$2:$D$100,14) -> 0 | E15: =INDEX(Question_Map!$E$2:$E$100,14) -> 0 | F15: =IF($C15<>"Scale","",COUNTIF(INDEX(Raw_Responses!$1:$1048576,0,MATCH($A15,Raw_Responses!$1:$1,0)),1)) | G15: =IF($C15<>"Scale","",COUNTIF(INDEX(Raw_Responses!$1:$1048576,0,MATCH($A15,Raw_Responses!$1:$1,0)),2)) | H15: =IF($C15<>"Scale","",COUNTIF(INDEX(Raw_Responses!$1:$1048576,0,MATCH($A15,Raw_Responses!$1:$1,0)),3)) | I15: =IF($C15<>"Scale","",COUNTIF(INDEX(Raw_Responses!$1:$1048576,0,MATCH($A15,Raw_Responses!$1:$1,0)),4)) | J15: =IF($C15<>"Scale","",COUNTIF(INDEX(Raw_Responses!$1:$1048576,0,MATCH($A15,Raw_Responses!$1:$1,0)),5)) | K15: =IF($C15<>"Scale","",COUNTIF(INDEX(Raw_Responses!$1:$1048576,0,MATCH($A15,Raw_Responses!$1:$1,0)),6)) | L15: =IF($C15<>"Scale","",COUNTIF(INDEX(Raw_Responses!$1:$1048576,0,MATCH($A15,Raw_Responses!$1:$1,0)),7)) | M15: =IF($C15<>"Scale","",COUNTIF(INDEX(Raw_Responses!$1:$1048576,0,MATCH($A15,Raw_Responses!$1:$1,0)),8)) | N15: =IF($C15<>"Scale","",COUNTIF(INDEX(Raw_Responses!$1:$1048576,0,MATCH($A15,Raw_Responses!$1:$1,0)),9)) | O15: =IF($C15<>"Scale","",COUNTIF(INDEX(Raw_Responses!$1:$1048576,0,MATCH($A15,Raw_Responses!$1:$1,0)),10))
A16: =INDEX(Question_Map!$A$2:$A$100,15) -> 0 | B16: =INDEX(Question_Map!$B$2:$B$100,15) -> 0 | C16: =INDEX(Question_Map!$C$2:$C$100,15) -> 0 | D16: =INDEX(Question_Map!$D$2:$D$100,15) -> 0 | E16: =INDEX(Question_Map!$E$2:$E$100,15) -> 0 | F16: =IF($C16<>"Scale","",COUNTIF(INDEX(Raw_Responses!$1:$1048576,0,MATCH($A16,Raw_Responses!$1:$1,0)),1)) | G16: =IF($C16<>"Scale","",COUNTIF(INDEX(Raw_Responses!$1:$1048576,0,MATCH($A16,Raw_Responses!$1:$1,0)),2)) | H16: =IF($C16<>"Scale","",COUNTIF(INDEX(Raw_Responses!$1:$1048576,0,MATCH($A16,Raw_Responses!$1:$1,0)),3)) | I16: =IF($C16<>"Scale","",COUNTIF(INDEX(Raw_Responses!$1:$1048576,0,MATCH($A16,Raw_Responses!$1:$1,0)),4)) | J16: =IF($C16<>"Scale","",COUNTIF(INDEX(Raw_Responses!$1:$1048576,0,MATCH($A16,Raw_Responses!$1:$1,0)),5)) | K16: =IF($C16<>"Scale","",COUNTIF(INDEX(Raw_Responses!$1:$1048576,0,MATCH($A16,Raw_Responses!$1:$1,0)),6)) | L16: =IF($C16<>"Scale","",COUNTIF(INDEX(Raw_Responses!$1:$1048576,0,MATCH($A16,Raw_Responses!$1:$1,0)),7)) | M16: =IF($C16<>"Scale","",COUNTIF(INDEX(Raw_Responses!$1:$1048576,0,MATCH($A16,Raw_Responses!$1:$1,0)),8)) | N16: =IF($C16<>"Scale","",COUNTIF(INDEX(Raw_Responses!$1:$1048576,0,MATCH($A16,Raw_Responses!$1:$1,0)),9)) | O16: =IF($C16<>"Scale","",COUNTIF(INDEX(Raw_Responses!$1:$1048576,0,MATCH($A16,Raw_Responses!$1:$1,0)),10))
A17: =INDEX(Question_Map!$A$2:$A$100,16) -> 0 | B17: =INDEX(Question_Map!$B$2:$B$100,16) -> 0 | C17: =INDEX(Question_Map!$C$2:$C$100,16) -> 0 | D17: =INDEX(Question_Map!$D$2:$D$100,16) -> 0 | E17: =INDEX(Question_Map!$E$2:$E$100,16) -> 0 | F17: =IF($C17<>"Scale","",COUNTIF(INDEX(Raw_Responses!$1:$1048576,0,MATCH($A17,Raw_Responses!$1:$1,0)),1)) | G17: =IF($C17<>"Scale","",COUNTIF(INDEX(Raw_Responses!$1:$1048576,0,MATCH($A17,Raw_Responses!$1:$1,0)),2)) | H17: =IF($C17<>"Scale","",COUNTIF(INDEX(Raw_Responses!$1:$1048576,0,MATCH($A17,Raw_Responses!$1:$1,0)),3)) | I17: =IF($C17<>"Scale","",COUNTIF(INDEX(Raw_Responses!$1:$1048576,0,MATCH($A17,Raw_Responses!$1:$1,0)),4)) | J17: =IF($C17<>"Scale","",COUNTIF(INDEX(Raw_Responses!$1:$1048576,0,MATCH($A17,Raw_Responses!$1:$1,0)),5)) | K17: =IF($C17<>"Scale","",COUNTIF(INDEX(Raw_Responses!$1:$1048576,0,MATCH($A17,Raw_Responses!$1:$1,0)),6)) | L17: =IF($C17<>"Scale","",COUNTIF(INDEX(Raw_Responses!$1:$1048576,0,MATCH($A17,Raw_Responses!$1:$1,0)),7)) | M17: =IF($C17<>"Scale","",COUNTIF(INDEX(Raw_Responses!$1:$1048576,0,MATCH($A17,Raw_Responses!$1:$1,0)),8)) | N17: =IF($C17<>"Scale","",COUNTIF(INDEX(Raw_Responses!$1:$1048576,0,MATCH($A17,Raw_Responses!$1:$1,0)),9)) | O17: =IF($C17<>"Scale","",COUNTIF(INDEX(Raw_Responses!$1:$1048576,0,MATCH($A17,Raw_Responses!$1:$1,0)),10))
A18: =INDEX(Question_Map!$A$2:$A$100,17) -> 0 | B18: =INDEX(Question_Map!$B$2:$B$100,17) -> 0 | C18: =INDEX(Question_Map!$C$2:$C$100,17) -> 0 | D18: =INDEX(Question_Map!$D$2:$D$100,17) -> 0 | E18: =INDEX(Question_Map!$E$2:$E$100,17) -> 0 | F18: =IF($C18<>"Scale","",COUNTIF(INDEX(Raw_Responses!$1:$1048576,0,MATCH($A18,Raw_Responses!$1:$1,0)),1)) | G18: =IF($C18<>"Scale","",COUNTIF(INDEX(Raw_Responses!$1:$1048576,0,MATCH($A18,Raw_Responses!$1:$1,0)),2)) | H18: =IF($C18<>"Scale","",COUNTIF(INDEX(Raw_Responses!$1:$1048576,0,MATCH($A18,Raw_Responses!$1:$1,0)),3)) | I18: =IF($C18<>"Scale","",COUNTIF(INDEX(Raw_Responses!$1:$1048576,0,MATCH($A18,Raw_Responses!$1:$1,0)),4)) | J18: =IF($C18<>"Scale","",COUNTIF(INDEX(Raw_Responses!$1:$1048576,0,MATCH($A18,Raw_Responses!$1:$1,0)),5)) | K18: =IF($C18<>"Scale","",COUNTIF(INDEX(Raw_Responses!$1:$1048576,0,MATCH($A18,Raw_Responses!$1:$1,0)),6)) | L18: =IF($C18<>"Scale","",COUNTIF(INDEX(Raw_Responses!$1:$1048576,0,MATCH($A18,Raw_Responses!$1:$1,0)),7)) | M18: =IF($C18<>"Scale","",COUNTIF(INDEX(Raw_Responses!$1:$1048576,0,MATCH($A18,Raw_Responses!$1:$1,0)),8)) | N18: =IF($C18<>"Scale","",COUNTIF(INDEX(Raw_Responses!$1:$1048576,0,MATCH($A18,Raw_Responses!$1:$1,0)),9)) | O18: =IF($C18<>"Scale","",COUNTIF(INDEX(Raw_Responses!$1:$1048576,0,MATCH($A18,Raw_Responses!$1:$1,0)),10))
A19: =INDEX(Question_Map!$A$2:$A$100,18) -> 0 | B19: =INDEX(Question_Map!$B$2:$B$100,18) -> 0 | C19: =INDEX(Question_Map!$C$2:$C$100,18) -> 0 | D19: =INDEX(Question_Map!$D$2:$D$100,18) -> 0 | E19: =INDEX(Question_Map!$E$2:$E$100,18) -> 0 | F19: =IF($C19<>"Scale","",COUNTIF(INDEX(Raw_Responses!$1:$1048576,0,MATCH($A19,Raw_Responses!$1:$1,0)),1)) | G19: =IF($C19<>"Scale","",COUNTIF(INDEX(Raw_Responses!$1:$1048576,0,MATCH($A19,Raw_Responses!$1:$1,0)),2)) | H19: =IF($C19<>"Scale","",COUNTIF(INDEX(Raw_Responses!$1:$1048576,0,MATCH($A19,Raw_Responses!$1:$1,0)),3)) | I19: =IF($C19<>"Scale","",COUNTIF(INDEX(Raw_Responses!$1:$1048576,0,MATCH($A19,Raw_Responses!$1:$1,0)),4)) | J19: =IF($C19<>"Scale","",COUNTIF(INDEX(Raw_Responses!$1:$1048576,0,MATCH($A19,Raw_Responses!$1:$1,0)),5)) | K19: =IF($C19<>"Scale","",COUNTIF(INDEX(Raw_Responses!$1:$1048576,0,MATCH($A19,Raw_Responses!$1:$1,0)),6)) | L19: =IF($C19<>"Scale","",COUNTIF(INDEX(Raw_Responses!$1:$1048576,0,MATCH($A19,Raw_Responses!$1:$1,0)),7)) | M19: =IF($C19<>"Scale","",COUNTIF(INDEX(Raw_Responses!$1:$1048576,0,MATCH($A19,Raw_Responses!$1:$1,0)),8)) | N19: =IF($C19<>"Scale","",COUNTIF(INDEX(Raw_Responses!$1:$1048576,0,MATCH($A19,Raw_Responses!$1:$1,0)),9)) | O19: =IF($C19<>"Scale","",COUNTIF(INDEX(Raw_Responses!$1:$1048576,0,MATCH($A19,Raw_Responses!$1:$1,0)),10))
A20: =INDEX(Question_Map!$A$2:$A$100,19) -> 0 | B20: =INDEX(Question_Map!$B$2:$B$100,19) -> 0 | C20: =INDEX(Question_Map!$C$2:$C$100,19) -> 0 | D20: =INDEX(Question_Map!$D$2:$D$100,19) -> 0 | E20: =INDEX(Question_Map!$E$2:$E$100,19) -> 0 | F20: =IF($C20<>"Scale","",COUNTIF(INDEX(Raw_Responses!$1:$1048576,0,MATCH($A20,Raw_Responses!$1:$1,0)),1)) | G20: =IF($C20<>"Scale","",COUNTIF(INDEX(Raw_Responses!$1:$1048576,0,MATCH($A20,Raw_Responses!$1:$1,0)),2)) | H20: =IF($C20<>"Scale","",COUNTIF(INDEX(Raw_Responses!$1:$1048576,0,MATCH($A20,Raw_Responses!$1:$1,0)),3)) | I20: =IF($C20<>"Scale","",COUNTIF(INDEX(Raw_Responses!$1:$1048576,0,MATCH($A20,Raw_Responses!$1:$1,0)),4)) | J20: =IF($C20<>"Scale","",COUNTIF(INDEX(Raw_Responses!$1:$1048576,0,MATCH($A20,Raw_Responses!$1:$1,0)),5)) | K20: =IF($C20<>"Scale","",COUNTIF(INDEX(Raw_Responses!$1:$1048576,0,MATCH($A20,Raw_Responses!$1:$1,0)),6)) | L20: =IF($C20<>"Scale","",COUNTIF(INDEX(Raw_Responses!$1:$1048576,0,MATCH($A20,Raw_Responses!$1:$1,0)),7)) | M20: =IF($C20<>"Scale","",COUNTIF(INDEX(Raw_Responses!$1:$1048576,0,MATCH($A20,Raw_Responses!$1:$1,0)),8)) | N20: =IF($C20<>"Scale","",COUNTIF(INDEX(Raw_Responses!$1:$1048576,0,MATCH($A20,Raw_Responses!$1:$1,0)),9)) | O20: =IF($C20<>"Scale","",COUNTIF(INDEX(Raw_Responses!$1:$1048576,0,MATCH($A20,Raw_Responses!$1:$1,0)),10))
A21: =INDEX(Question_Map!$A$2:$A$100,20) -> 0 | B21: =INDEX(Question_Map!$B$2:$B$100,20) -> 0 | C21: =INDEX(Question_Map!$C$2:$C$100,20) -> 0 | D21: =INDEX(Question_Map!$D$2:$D$100,20) -> 0 | E21: =INDEX(Question_Map!$E$2:$E$100,20) -> 0 | F21: =IF($C21<>"Scale","",COUNTIF(INDEX(Raw_Responses!$1:$1048576,0,MATCH($A21,Raw_Responses!$1:$1,0)),1)) | G21: =IF($C21<>"Scale","",COUNTIF(INDEX(Raw_Responses!$1:$1048576,0,MATCH($A21,Raw_Responses!$1:$1,0)),2)) | H21: =IF($C21<>"Scale","",COUNTIF(INDEX(Raw_Responses!$1:$1048576,0,MATCH($A21,Raw_Responses!$1:$1,0)),3)) | I21: =IF($C21<>"Scale","",COUNTIF(INDEX(Raw_Responses!$1:$1048576,0,MATCH($A21,Raw_Responses!$1:$1,0)),4)) | J21: =IF($C21<>"Scale","",COUNTIF(INDEX(Raw_Responses!$1:$1048576,0,MATCH($A21,Raw_Responses!$1:$1,0)),5)) | K21: =IF($C21<>"Scale","",COUNTIF(INDEX(Raw_Responses!$1:$1048576,0,MATCH($A21,Raw_Responses!$1:$1,0)),6)) | L21: =IF($C21<>"Scale","",COUNTIF(INDEX(Raw_Responses!$1:$1048576,0,MATCH($A21,Raw_Responses!$1:$1,0)),7)) | M21: =IF($C21<>"Scale","",COUNTIF(INDEX(Raw_Responses!$1:$1048576,0,MATCH($A21,Raw_Responses!$1:$1,0)),8)) | N21: =IF($C21<>"Scale","",COUNTIF(INDEX(Raw_Responses!$1:$1048576,0,MATCH($A21,Raw_Responses!$1:$1,0)),9)) | O21: =IF($C21<>"Scale","",COUNTIF(INDEX(Raw_Responses!$1:$1048576,0,MATCH($A21,Raw_Responses!$1:$1,0)),10))

Sheet MCQ_Summary
A1: Header (MCQ) | B1: Option | C1: Count
C2: =IF($A2="","",COUNTIF(INDEX(Raw_Responses!$1:$1048576,0,MATCH($A2,Raw_Responses!$1:$1,0)),$B2))
C3: =IF($A3="","",COUNTIF(INDEX(Raw_Responses!$1:$1048576,0,MATCH($A3,Raw_Responses!$1:$1,0)),$B3))
C4: =IF($A4="","",COUNTIF(INDEX(Raw_Responses!$1:$1048576,0,MATCH($A4,Raw_Responses!$1:$1,0)),$B4))
C5: =IF($A5="","",COUNTIF(INDEX(Raw_Responses!$1:$1048576,0,MATCH($A5,Raw_Responses!$1:$1,0)),$B5))
C6: =IF($A6="","",COUNTIF(INDEX(Raw_Responses!$1:$1048576,0,MATCH($A6,Raw_Responses!$1:$1,0)),$B6))
C7: =IF($A7="","",COUNTIF(INDEX(Raw_Responses!$1:$1048576,0,MATCH($A7,Raw_Responses!$1:$1,0)),$B7))
C8: =IF($A8="","",COUNTIF(INDEX(Raw_Responses!$1:$1048576,0,MATCH($A8,Raw_Responses!$1:$1,0)),$B8))
C9: =IF($A9="","",COUNTIF(INDEX(Raw_Responses!$1:$1048576,0,MATCH($A9,Raw_Responses!$1:$1,0)),$B9))
C10: =IF($A10="","",COUNTIF(INDEX(Raw_Responses!$1:$1048576,0,MATCH($A10,Raw_Responses!$1:$1,0)),$B10))
C11: =IF($A11="","",COUNTIF(INDEX(Raw_Responses!$1:$1048576,0,MATCH($A11,Raw_Responses!$1:$1,0)),$B11))
C12: =IF($A12="","",COUNTIF(INDEX(Raw_Responses!$1:$1048576,0,MATCH($A12,Raw_Responses!$1:$1,0)),$B12))
C13: =IF($A13="","",COUNTIF(INDEX(Raw_Responses!$1:$1048576,0,MATCH($A13,Raw_Responses!$1:$1,0)),$B13))
... C21: =IF($A21="","",COUNTIF(INDEX(Raw_Responses!$1:$1048576,0,MATCH($A21,Raw_Responses!$1:$1,0)),$B21))

Sheet Dashboard
A1: Scale Question Averages (first 10 from Question_Map marked as Scale)
A3: Header | B3: Average
A4: =Scales_Averages!$A$2 -> I could complete the key tasks without help. | B4: =Scales_Averages!$E$2 -> 0
A5: =Scales_Averages!$A$3 -> Labels and buttons were clear. | B5: =Scales_Averages!$E$3 -> 0
A6: =Scales_Averages!$A$4 -> The layout was easy to navigate. | B6: =Scales_Averages!$E$4 -> 0
A7: =Scales_Averages!$A$5 -> Pages loaded fast enough. | B7: =Scales_Averages!$E$5 -> 0
A8: =Scales_Averages!$A$6 -> It worked comfortably on my phone/tablet. | B8: =Scales_Averages!$E$6 -> 0
A9: =Scales_Averages!$A$7 -> Overall, it meets my needs. | B9: =Scales_Averages!$E$7 -> 0
A10: =Scales_Averages!$A$8 | B10: =Scales_Averages!$E$8
